Workbook

Sheet Calculations
A1: x | B1: Left/Right
A2: y | B2: Up/Down
A3: z | B3: Forward/Backward
B7: z | C7: x | D7: y
A8: Marker 1 | B8: 50 | C8: 20 | D8: 0
A9: Marker 2 | B9: 80 | C9: 80 | D9: 0
A10: Marker 3 | B10: 20 | C10: 80 | D10: 0
B12: Slope | C12: Intercept
A13: 1 -> 2 | B13: =(C9-C8)/(B9-B8) -> 2 | C13: =C8-B13*B8 -> -80
A14: 2 -> 3 | B14: =(C10-C9)/(B10-B9) -> 0 | C14: =C9-B14*B9 -> 80
A15: 3 -> 1 | B15: =(C8-C10)/(B8-B10) -> -2 | C15: =C10-B15*B10 -> 120
B17: Equations
A18: 1 -> 2 | B18: y = 2x-80
A19: 2 -> 3 | B19: y = 80
A20: 3 -> 1 | B20: y = -2x+120

Sheet Data
A1: time | B1: z | C1: x | D1: y | E1: vel | F1: accel | G1: rot | H1: UserForce | I1: Voltage1 | J1: Voltage2 | K1: Voltage3
A2: 0 | B2: 50 | C2: 20 | D2: 0 | E2: 0 | F2: 0 | G2: 0 | H2: =(SystemConstants!$B$6*F2)+(0.5*SystemConstants!$B$7*SystemConstants!$B$5*Data!E2^2)+(0.5*SystemConstants!$B$7*SystemConstants!$B$2*SystemConstants!$B$3*Data!E2^2) -> 0
A3: =A2+1 -> 1 | B3: =B2+(30/180) -> 50.166667 | C3: =2*Data!B3-80 -> 20.333333 | D3: 0 | E3: =ABS((SQRT(B3^2+C3^2+D3^2)-SQRT(B2^2+C2^2+D2^2))/(A3-A2)) -> 0.27910926 | F3: =(E3-E2)/(A3-A2) -> 0.27910926 | G3: =DEGREES(ACOS( (B2*B3+C2*C3+D2*D3) / SQRT((B2^2+C2^2+D2^2)*(B3^2+C3^2+D3^2)))) -> 0.26207149 | H3: =(SystemConstants!$B$6*F3)+(0.5*SystemConstants!$B$7*SystemConstants!$B$5*Data!E3^2)+(0.5*SystemConstants!$B$7*SystemConstants!$B$2*SystemConstants!$B$3*Data!E3^2) -> 44.836314
A4: =A3+1 -> 2 | B4: =B3+(30/180) -> 50.333333 | C4: =2*Data!B4-80 -> 20.666667 | D4: 0 | E4: =ABS((SQRT(B4^2+C4^2+D4^2)-SQRT(B3^2+C3^2+D3^2))/(A4-A3)) -> 0.28023012 | F4: =(E4-E3)/(A4-A3) -> 0.0011208681 | G4: =DEGREES(ACOS( (B3*B4+C3*C4+D3*D4) / SQRT((B3^2+C3^2+D3^2)*(B4^2+C4^2+D4^2)))) -> 0.25937741 | H4: =(SystemConstants!$B$6*F4)+(0.5*SystemConstants!$B$7*SystemConstants!$B$5*Data!E4^2)+(0.5*SystemConstants!$B$7*SystemConstants!$B$2*SystemConstants!$B$3*Data!E4^2) -> 44.916916
A5: =A4+1 -> 3 | B5: =B4+(30/180) -> 50.5 | C5: =2*Data!B5-80 -> 21 | D5: 0 | E5: =ABS((SQRT(B5^2+C5^2+D5^2)-SQRT(B4^2+C4^2+D4^2))/(A5-A4)) -> 0.28133376 | F5: =(E5-E4)/(A5-A4) -> 0.0011036389 | G5: =DEGREES(ACOS( (B4*B5+C4*C5+D4*D5) / SQRT((B4^2+C4^2+D4^2)*(B5^2+C5^2+D5^2)))) -> 0.25671418 | H5: =(SystemConstants!$B$6*F5)+(0.5*SystemConstants!$B$7*SystemConstants!$B$5*Data!E5^2)+(0.5*SystemConstants!$B$7*SystemConstants!$B$2*SystemConstants!$B$3*Data!E5^2) -> 45.271382
A6: =A5+1 -> 4 | B6: =B5+(30/180) -> 50.666667 | C6: =2*Data!B6-80 -> 21.333333 | D6: 0 | E6: =ABS((SQRT(B6^2+C6^2+D6^2)-SQRT(B5^2+C5^2+D5^2))/(A6-A5)) -> 0.28242046 | F6: =(E6-E5)/(A6-A5) -> 0.0010866953 | G6: =DEGREES(ACOS( (B5*B6+C5*C6+D5*D6) / SQRT((B5^2+C5^2+D5^2)*(B6^2+C6^2+D6^2)))) -> 0.25408161 | H6: =(SystemConstants!$B$6*F6)+(0.5*SystemConstants!$B$7*SystemConstants!$B$5*Data!E6^2)+(0.5*SystemConstants!$B$7*SystemConstants!$B$2*SystemConstants!$B$3*Data!E6^2) -> 45.621768
A7: =A6+1 -> 5 | B7: =B6+(30/180) -> 50.833333 | C7: =2*Data!B7-80 -> 21.666667 | D7: 0 | E7: =ABS((SQRT(B7^2+C7^2+D7^2)-SQRT(B6^2+C6^2+D6^2))/(A7-A6)) -> 0.28349049 | F7: =(E7-E6)/(A7-A6) -> 0.0010700333 | G7: =DEGREES(ACOS( (B6*B7+C6*C7+D6*D7) / SQRT((B6^2+C6^2+D6^2)*(B7^2+C7^2+D7^2)))) -> 0.25147949 | H7: =(SystemConstants!$B$6*F7)+(0.5*SystemConstants!$B$7*SystemConstants!$B$5*Data!E7^2)+(0.5*SystemConstants!$B$7*SystemConstants!$B$2*SystemConstants!$B$3*Data!E7^2) -> 45.968101
A8: =A7+1 -> 6 | B8: =B7+(30/180) -> 51 | C8: =2*Data!B8-80 -> 22 | D8: 0 | E8: =ABS((SQRT(B8^2+C8^2+D8^2)-SQRT(B7^2+C7^2+D7^2))/(A8-A7)) -> 0.28454414 | F8: =(E8-E7)/(A8-A7) -> 0.0010536489 | G8: =DEGREES(ACOS( (B7*B8+C7*C8+D7*D8) / SQRT((B7^2+C7^2+D7^2)*(B8^2+C8^2+D8^2)))) -> 0.2489076 | H8: =(SystemConstants!$B$6*F8)+(0.5*SystemConstants!$B$7*SystemConstants!$B$5*Data!E8^2)+(0.5*SystemConstants!$B$7*SystemConstants!$B$2*SystemConstants!$B$3*Data!E8^2) -> 46.31041
A9: =A8+1 -> 7 | B9: =B8+(30/180) -> 51.166667 | C9: =2*Data!B9-80 -> 22.333333 | D9: 0 | E9: =ABS((SQRT(B9^2+C9^2+D9^2)-SQRT(B8^2+C8^2+D8^2))/(A9-A8)) -> 0.28558168 | F9: =(E9-E8)/(A9-A8) -> 0.0010375383 | G9: =DEGREES(ACOS( (B8*B9+C8*C9+D8*D9) / SQRT((B8^2+C8^2+D8^2)*(B9^2+C9^2+D9^2)))) -> 0.24636571 | H9: =(SystemConstants!$B$6*F9)+(0.5*SystemConstants!$B$7*SystemConstants!$B$5*Data!E9^2)+(0.5*SystemConstants!$B$7*SystemConstants!$B$2*SystemConstants!$B$3*Data!E9^2) -> 46.648727
A10: =A9+1 -> 8 | B10: =B9+(30/180) -> 51.333333 | C10: =2*Data!B10-80 -> 22.666667 | D10: 0 | E10: =ABS((SQRT(B10^2+C10^2+D10^2)-SQRT(B9^2+C9^2+D9^2))/(A10-A9)) -> 0.28660338 | F10: =(E10-E9)/(A10-A9) -> 0.0010216975 | G10: =DEGREES(ACOS( (B9*B10+C9*C10+D9*D10) / SQRT((B9^2+C9^2+D9^2)*(B10^2+C10^2+D10^2)))) -> 0.24385359 | H10: =(SystemConstants!$B$6*F10)+(0.5*SystemConstants!$B$7*SystemConstants!$B$5*Data!E10^2)+(0.5*SystemConstants!$B$7*SystemConstants!$B$2*SystemConstants!$B$3*Data!E10^2) -> 46.983082
A11: =A10+1 -> 9 | B11: =B10+(30/180) -> 51.5 | C11: =2*Data!B11-80 -> 23 | D11: 0 | E11: =ABS((SQRT(B11^2+C11^2+D11^2)-SQRT(B10^2+C10^2+D10^2))/(A11-A10)) -> 0.2876095 | F11: =(E11-E10)/(A11-A10) -> 0.0010061226 | G11: =DEGREES(ACOS( (B10*B11+C10*C11+D10*D11) / SQRT((B10^2+C10^2+D10^2)*(B11^2+C11^2+D11^2)))) -> 0.241371 | H11: =(SystemConstants!$B$6*F11)+(0.5*SystemConstants!$B$7*SystemConstants!$B$5*Data!E11^2)+(0.5*SystemConstants!$B$7*SystemConstants!$B$2*SystemConstants!$B$3*Data!E11^2) -> 47.313507
A12: =A11+1 -> 10 | B12: =B11+(30/180) -> 51.666667 | C12: =2*Data!B12-80 -> 23.333333 | D12: 0 | E12: =ABS((SQRT(B12^2+C12^2+D12^2)-SQRT(B11^2+C11^2+D11^2))/(A12-A11)) -> 0.28860031 | F12: =(E12-E11)/(A12-A11) -> 0.00099080958 | G12: =DEGREES(ACOS( (B11*B12+C11*C12+D11*D12) / SQRT((B11^2+C11^2+D11^2)*(B12^2+C12^2+D12^2)))) -> 0.23891769 | H12: =(SystemConstants!$B$6*F12)+(0.5*SystemConstants!$B$7*SystemConstants!$B$5*Data!E12^2)+(0.5*SystemConstants!$B$7*SystemConstants!$B$2*SystemConstants!$B$3*Data!E12^2) -> 47.640035
A13: =A12+1 -> 11 | B13: =B12+(30/180) -> 51.833333 | C13: =2*Data!B13-80 -> 23.666667 | D13: 0 | E13: =ABS((SQRT(B13^2+C13^2+D13^2)-SQRT(B12^2+C12^2+D12^2))/(A13-A12)) -> 0.28957606 | F13: =(E13-E12)/(A13-A12) -> 0.00097575461 | G13: =DEGREES(ACOS( (B12*B13+C12*C13+D12*D13) / SQRT((B12^2+C12^2+D12^2)*(B13^2+C13^2+D13^2)))) -> 0.2364934 | H13: =(SystemConstants!$B$6*F13)+(0.5*SystemConstants!$B$7*SystemConstants!$B$5*Data!E13^2)+(0.5*SystemConstants!$B$7*SystemConstants!$B$2*SystemConstants!$B$3*Data!E13^2) -> 47.962698
A14: =A13+1 -> 12 | B14: =B13+(30/180) -> 52 | C14: =2*Data!B14-80 -> 24 | D14: 0 | E14: =ABS((SQRT(B14^2+C14^2+D14^2)-SQRT(B13^2+C13^2+D13^2))/(A14-A13)) -> 0.29053702 | F14: =(E14-E13)/(A14-A13) -> 0.00096095373 | G14: =DEGREES(ACOS( (B13*B14+C13*C14+D13*D14) / SQRT((B13^2+C13^2+D13^2)*(B14^2+C14^2+D14^2)))) -> 0.2340979 | H14: =(SystemConstants!$B$6*F14)+(0.5*SystemConstants!$B$7*SystemConstants!$B$5*Data!E14^2)+(0.5*SystemConstants!$B$7*SystemConstants!$B$2*SystemConstants!$B$3*Data!E14^2) -> 48.281532
... A182: =A181+1 -> 180 | B182: =B181+(30/180) -> 80 | C182: =2*Data!B182-80 -> 80 | D182: 0 | E182: =ABS((SQRT(B182^2+C182^2+D182^2)-SQRT(B181^2+C181^2+D181^2))/(A182-A181)) -> 0.35349182 | F182: =(E182-E181)/(A182-A181) -> 0.00012392069 | G182: =DEGREES(ACOS( (B181*B182+C181*C182+D181*D182) / SQRT((B181^2+C181^2+D181^2)*(B182^2+C182^2+D182^2)))) -> 0.059870176 | H182: =(SystemConstants!$B$6*F182)+(0.5*SystemConstants!$B$7*SystemConstants!$B$5*Data!E182^2)+(0.5*SystemConstants!$B$7*SystemConstants!$B$2*SystemConstants!$B$3*Data!E182^2) -> 71.470848
A183: =A182+1 -> 181 | B183: =(B182-(60/180)) -> 79.666667 | C183: 80 | D183: 0 | E183: =ABS((SQRT(B183^2+C183^2+D183^2)-SQRT(B182^2+C182^2+D182^2))/(A183-A182)) -> 0.23545622 | F183: =(E183-E182)/(A183-A182) -> -0.11803559 | G183: =DEGREES(ACOS( (B182*B183+C182*C183+D182*D183) / SQRT((B182^2+C182^2+D182^2)*(B183^2+C183^2+D183^2)))) -> 0.11961523 | H183: =(SystemConstants!$B$6*F183)+(0.5*SystemConstants!$B$7*SystemConstants!$B$5*Data!E183^2)+(0.5*SystemConstants!$B$7*SystemConstants!$B$2*SystemConstants!$B$3*Data!E183^2) -> 31.591495
A184: =A183+1 -> 182 | B184: =(B183-(60/180)) -> 79.333333 | C184: 80 | D184: 0 | E184: =ABS((SQRT(B184^2+C184^2+D184^2)-SQRT(B183^2+C183^2+D183^2))/(A184-A183)) -> 0.2349621 | F184: =(E184-E183)/(A184-A183) -> -0.00049412662 | G184: =DEGREES(ACOS( (B183*B184+C183*C184+D183*D184) / SQRT((B183^2+C183^2+D183^2)*(B184^2+C184^2+D184^2)))) -> 0.12011466 | H184: =(SystemConstants!$B$6*F184)+(0.5*SystemConstants!$B$7*SystemConstants!$B$5*Data!E184^2)+(0.5*SystemConstants!$B$7*SystemConstants!$B$2*SystemConstants!$B$3*Data!E184^2) -> 31.576085
A185: =A184+1 -> 183 | B185: =(B184-(60/180)) -> 79 | C185: 80 | D185: 0 | E185: =ABS((SQRT(B185^2+C185^2+D185^2)-SQRT(B184^2+C184^2+D184^2))/(A185-A184)) -> 0.23446487 | F185: =(E185-E184)/(A185-A184) -> -0.00049722452 | G185: =DEGREES(ACOS( (B184*B185+C184*C185+D184*D185) / SQRT((B184^2+C184^2+D184^2)*(B185^2+C185^2+D185^2)))) -> 0.12061617 | H185: =(SystemConstants!$B$6*F185)+(0.5*SystemConstants!$B$7*SystemConstants!$B$5*Data!E185^2)+(0.5*SystemConstants!$B$7*SystemConstants!$B$2*SystemConstants!$B$3*Data!E185^2) -> 31.442579
A186: =A185+1 -> 184 | B186: =(B185-(60/180)) -> 78.666667 | C186: 80 | D186: 0 | E186: =ABS((SQRT(B186^2+C186^2+D186^2)-SQRT(B185^2+C185^2+D185^2))/(A186-A185)) -> 0.23396453 | F186: =(E186-E185)/(A186-A185) -> -0.00050034172 | G186: =DEGREES(ACOS( (B185*B186+C185*C186+D185*D186) / SQRT((B185^2+C185^2+D185^2)*(B186^2+C186^2+D186^2)))) -> 0.12111974 | H186: =(SystemConstants!$B$6*F186)+(0.5*SystemConstants!$B$7*SystemConstants!$B$5*Data!E186^2)+(0.5*SystemConstants!$B$7*SystemConstants!$B$2*SystemConstants!$B$3*Data!E186^2) -> 31.308522
A187: =A186+1 -> 185 | B187: =(B186-(60/180)) -> 78.333333 | C187: 80 | D187: 0 | E187: =ABS((SQRT(B187^2+C187^2+D187^2)-SQRT(B186^2+C186^2+D186^2))/(A187-A186)) -> 0.23346105 | F187: =(E187-E186)/(A187-A186) -> -0.0005034783 | G187: =DEGREES(ACOS( (B186*B187+C186*C187+D186*D187) / SQRT((B186^2+C186^2+D186^2)*(B187^2+C187^2+D187^2)))) -> 0.12162539 | H187: =(SystemConstants!$B$6*F187)+(0.5*SystemConstants!$B$7*SystemConstants!$B$5*Data!E187^2)+(0.5*SystemConstants!$B$7*SystemConstants!$B$2*SystemConstants!$B$3*Data!E187^2) -> 31.173913
A188: =A187+1 -> 186 | B188: =(B187-(60/180)) -> 78 | C188: 80 | D188: 0 | E188: =ABS((SQRT(B188^2+C188^2+D188^2)-SQRT(B187^2+C187^2+D187^2))/(A188-A187)) -> 0.23295442 | F188: =(E188-E187)/(A188-A187) -> -0.00050663432 | G188: =DEGREES(ACOS( (B187*B188+C187*C188+D187*D188) / SQRT((B187^2+C187^2+D187^2)*(B188^2+C188^2+D188^2)))) -> 0.1221331 | H188: =(SystemConstants!$B$6*F188)+(0.5*SystemConstants!$B$7*SystemConstants!$B$5*Data!E188^2)+(0.5*SystemConstants!$B$7*SystemConstants!$B$2*SystemConstants!$B$3*Data!E188^2) -> 31.038754
A189: =A188+1 -> 187 | B189: =(B188-(60/180)) -> 77.666667 | C189: 80 | D189: 0 | E189: =ABS((SQRT(B189^2+C189^2+D189^2)-SQRT(B188^2+C188^2+D188^2))/(A189-A188)) -> 0.23244461 | F189: =(E189-E188)/(A189-A188) -> -0.00050980984 | G189: =DEGREES(ACOS( (B188*B189+C188*C189+D188*D189) / SQRT((B188^2+C188^2+D188^2)*(B189^2+C189^2+D189^2)))) -> 0.12264289 | H189: =(SystemConstants!$B$6*F189)+(0.5*SystemConstants!$B$7*SystemConstants!$B$5*Data!E189^2)+(0.5*SystemConstants!$B$7*SystemConstants!$B$2*SystemConstants!$B$3*Data!E189^2) -> 30.903043
A190: =A189+1 -> 188 | B190: =(B189-(60/180)) -> 77.333333 | C190: 80 | D190: 0 | E190: =ABS((SQRT(B190^2+C190^2+D190^2)-SQRT(B189^2+C189^2+D189^2))/(A190-A189)) -> 0.2319316 | F190: =(E190-E189)/(A190-A189) -> -0.00051300491 | G190: =DEGREES(ACOS( (B189*B190+C189*C190+D189*D190) / SQRT((B189^2+C189^2+D189^2)*(B190^2+C190^2+D190^2)))) -> 0.12315474 | H190: =(SystemConstants!$B$6*F190)+(0.5*SystemConstants!$B$7*SystemConstants!$B$5*Data!E190^2)+(0.5*SystemConstants!$B$7*SystemConstants!$B$2*SystemConstants!$B$3*Data!E190^2) -> 30.766782
A191: =A190+1 -> 189 | B191: =(B190-(60/180)) -> 77 | C191: 80 | D191: 0 | E191: =ABS((SQRT(B191^2+C191^2+D191^2)-SQRT(B190^2+C190^2+D190^2))/(A191-A190)) -> 0.23141539 | F191: =(E191-E190)/(A191-A190) -> -0.0005162196 | G191: =DEGREES(ACOS( (B190*B191+C190*C191+D190*D191) / SQRT((B190^2+C190^2+D190^2)*(B191^2+C191^2+D191^2)))) -> 0.12366866 | H191: =(SystemConstants!$B$6*F191)+(0.5*SystemConstants!$B$7*SystemConstants!$B$5*Data!E191^2)+(0.5*SystemConstants!$B$7*SystemConstants!$B$2*SystemConstants!$B$3*Data!E191^2) -> 30.629971
A192: =A191+1 -> 190 | B192: =(B191-(60/180)) -> 76.666667 | C192: 80 | D192: 0 | E192: =ABS((SQRT(B192^2+C192^2+D192^2)-SQRT(B191^2+C191^2+D191^2))/(A192-A191)) -> 0.23089593 | F192: =(E192-E191)/(A192-A191) -> -0.00051945396 | G192: =DEGREES(ACOS( (B191*B192+C191*C192+D191*D192) / SQRT((B191^2+C191^2+D191^2)*(B192^2+C192^2+D192^2)))) -> 0.12418464 | H192: =(SystemConstants!$B$6*F192)+(0.5*SystemConstants!$B$7*SystemConstants!$B$5*Data!E192^2)+(0.5*SystemConstants!$B$7*SystemConstants!$B$2*SystemConstants!$B$3*Data!E192^2) -> 30.492611
A193: =A192+1 -> 191 | B193: =(B192-(60/180)) -> 76.333333 | C193: 80 | D193: 0 | E193: =ABS((SQRT(B193^2+C193^2+D193^2)-SQRT(B192^2+C192^2+D192^2))/(A193-A192)) -> 0.23037322 | F193: =(E193-E192)/(A193-A192) -> -0.00052270804 | G193: =DEGREES(ACOS( (B192*B193+C192*C193+D192*D193) / SQRT((B192^2+C192^2+D192^2)*(B193^2+C193^2+D193^2)))) -> 0.12470269 | H193: =(SystemConstants!$B$6*F193)+(0.5*SystemConstants!$B$7*SystemConstants!$B$5*Data!E193^2)+(0.5*SystemConstants!$B$7*SystemConstants!$B$2*SystemConstants!$B$3*Data!E193^2) -> 30.354702
A194: =A193+1 -> 192 | B194: =(B193-(60/180)) -> 76 | C194: 80 | D194: 0 | E194: =ABS((SQRT(B194^2+C194^2+D194^2)-SQRT(B193^2+C193^2+D193^2))/(A194-A193)) -> 0.22984724 | F194: =(E194-E193)/(A194-A193) -> -0.0005259819 | G194: =DEGREES(ACOS( (B193*B194+C193*C194+D193*D194) / SQRT((B193^2+C193^2+D193^2)*(B194^2+C194^2+D194^2)))) -> 0.12522279 | H194: =(SystemConstants!$B$6*F194)+(0.5*SystemConstants!$B$7*SystemConstants!$B$5*Data!E194^2)+(0.5*SystemConstants!$B$7*SystemConstants!$B$2*SystemConstants!$B$3*Data!E194^2) -> 30.216244
... A362: =A361+1 -> 360 | B362: =(B361-(60/180)) -> 20 | C362: 80 | D362: 0 | E362: =ABS((SQRT(B362^2+C362^2+D362^2)-SQRT(B361^2+C361^2+D361^2))/(A362-A361)) -> 0.081478665 | F362: =(E362-E361)/(A362-A361) -> -0.0012644048 | G362: =DEGREES(ACOS( (B361*B362+C361*C362+D361*D362) / SQRT((B361^2+C361^2+D361^2)*(B362^2+C362^2+D362^2)))) -> 0.22446812 | H362: =(SystemConstants!$B$6*F362)+(0.5*SystemConstants!$B$7*SystemConstants!$B$5*Data!E362^2)+(0.5*SystemConstants!$B$7*SystemConstants!$B$2*SystemConstants!$B$3*Data!E362^2) -> 3.7958813
A363: =A362+1 -> 361 | B363: =B362+(30/180) -> 20.166667 | C363: =-2*B363+120 -> 79.666667 | D363: 0 | E363: =ABS((SQRT(B363^2+C363^2+D363^2)-SQRT(B362^2+C362^2+D362^2))/(A363-A362)) -> 0.28260033 | F363: =(E363-E362)/(A363-A362) -> 0.20112167 | G363: =DEGREES(ACOS( (B362*B363+C362*C363+D362*D363) / SQRT((B362^2+C362^2+D362^2)*(B363^2+C363^2+D363^2)))) -> 0.16909674 | H363: =(SystemConstants!$B$6*F363)+(0.5*SystemConstants!$B$7*SystemConstants!$B$5*Data!E363^2)+(0.5*SystemConstants!$B$7*SystemConstants!$B$2*SystemConstants!$B$3*Data!E363^2) -> 45.879932
A364: =A363+1 -> 362 | B364: =B363+(30/180) -> 20.333333 | C364: =-2*B364+120 -> 79.333333 | D364: 0 | E364: =ABS((SQRT(B364^2+C364^2+D364^2)-SQRT(B363^2+C363^2+D363^2))/(A364-A363)) -> 0.2818796 | F364: =(E364-E363)/(A364-A363) -> -0.00072073147 | G364: =DEGREES(ACOS( (B363*B364+C363*C364+D363*D364) / SQRT((B363^2+C363^2+D363^2)*(B364^2+C364^2+D364^2)))) -> 0.17026225 | H364: =(SystemConstants!$B$6*F364)+(0.5*SystemConstants!$B$7*SystemConstants!$B$5*Data!E364^2)+(0.5*SystemConstants!$B$7*SystemConstants!$B$2*SystemConstants!$B$3*Data!E364^2) -> 45.445393
A365: =A364+1 -> 363 | B365: =B364+(30/180) -> 20.5 | C365: =-2*B365+120 -> 79 | D365: 0 | E365: =ABS((SQRT(B365^2+C365^2+D365^2)-SQRT(B364^2+C364^2+D364^2))/(A365-A364)) -> 0.2811514 | F365: =(E365-E364)/(A365-A364) -> -0.00072819906 | G365: =DEGREES(ACOS( (B364*B365+C364*C365+D364*D365) / SQRT((B364^2+C364^2+D364^2)*(B365^2+C365^2+D365^2)))) -> 0.1714368 | H365: =(SystemConstants!$B$6*F365)+(0.5*SystemConstants!$B$7*SystemConstants!$B$5*Data!E365^2)+(0.5*SystemConstants!$B$7*SystemConstants!$B$2*SystemConstants!$B$3*Data!E365^2) -> 45.21088
A366: =A365+1 -> 364 | B366: =B365+(30/180) -> 20.666667 | C366: =-2*B366+120 -> 78.666667 | D366: 0 | E366: =ABS((SQRT(B366^2+C366^2+D366^2)-SQRT(B365^2+C365^2+D365^2))/(A366-A365)) -> 0.28041565 | F366: =(E366-E365)/(A366-A365) -> -0.00073575048 | G366: =DEGREES(ACOS( (B365*B366+C365*C366+D365*D366) / SQRT((B365^2+C365^2+D365^2)*(B366^2+C366^2+D366^2)))) -> 0.17262046 | H366: =(SystemConstants!$B$6*F366)+(0.5*SystemConstants!$B$7*SystemConstants!$B$5*Data!E366^2)+(0.5*SystemConstants!$B$7*SystemConstants!$B$2*SystemConstants!$B$3*Data!E366^2) -> 44.974552
A367: =A366+1 -> 365 | B367: =B366+(30/180) -> 20.833333 | C367: =-2*B367+120 -> 78.333333 | D367: 0 | E367: =ABS((SQRT(B367^2+C367^2+D367^2)-SQRT(B366^2+C366^2+D366^2))/(A367-A366)) -> 0.27967226 | F367: =(E367-E366)/(A367-A366) -> -0.00074338649 | G367: =DEGREES(ACOS( (B366*B367+C366*C367+D366*D367) / SQRT((B366^2+C366^2+D366^2)*(B367^2+C367^2+D367^2)))) -> 0.17381324 | H367: =(SystemConstants!$B$6*F367)+(0.5*SystemConstants!$B$7*SystemConstants!$B$5*Data!E367^2)+(0.5*SystemConstants!$B$7*SystemConstants!$B$2*SystemConstants!$B$3*Data!E367^2) -> 44.7364
A368: =A367+1 -> 366 | B368: =B367+(30/180) -> 21 | C368: =-2*B368+120 -> 78 | D368: 0 | E368: =ABS((SQRT(B368^2+C368^2+D368^2)-SQRT(B367^2+C367^2+D367^2))/(A368-A367)) -> 0.27892116 | F368: =(E368-E367)/(A368-A367) -> -0.00075110788 | G368: =DEGREES(ACOS( (B367*B368+C367*C368+D367*D368) / SQRT((B367^2+C367^2+D367^2)*(B368^2+C368^2+D368^2)))) -> 0.1750152 | H368: =(SystemConstants!$B$6*F368)+(0.5*SystemConstants!$B$7*SystemConstants!$B$5*Data!E368^2)+(0.5*SystemConstants!$B$7*SystemConstants!$B$2*SystemConstants!$B$3*Data!E368^2) -> 44.496417
A369: =A368+1 -> 367 | B369: =B368+(30/180) -> 21.166667 | C369: =-2*B369+120 -> 77.666667 | D369: 0 | E369: =ABS((SQRT(B369^2+C369^2+D369^2)-SQRT(B368^2+C368^2+D368^2))/(A369-A368)) -> 0.27816224 | F369: =(E369-E368)/(A369-A368) -> -0.00075891539 | G369: =DEGREES(ACOS( (B368*B369+C368*C369+D368*D369) / SQRT((B368^2+C368^2+D368^2)*(B369^2+C369^2+D369^2)))) -> 0.17622637 | H369: =(SystemConstants!$B$6*F369)+(0.5*SystemConstants!$B$7*SystemConstants!$B$5*Data!E369^2)+(0.5*SystemConstants!$B$7*SystemConstants!$B$2*SystemConstants!$B$3*Data!E369^2) -> 44.254594
A370: =A369+1 -> 368 | B370: =B369+(30/180) -> 21.333333 | C370: =-2*B370+120 -> 77.333333 | D370: 0 | E370: =ABS((SQRT(B370^2+C370^2+D370^2)-SQRT(B369^2+C369^2+D369^2))/(A370-A369)) -> 0.27739543 | F370: =(E370-E369)/(A370-A369) -> -0.0007668098 | G370: =DEGREES(ACOS( (B369*B370+C369*C370+D369*D370) / SQRT((B369^2+C369^2+D369^2)*(B370^2+C370^2+D370^2)))) -> 0.17744679 | H370: =(SystemConstants!$B$6*F370)+(0.5*SystemConstants!$B$7*SystemConstants!$B$5*Data!E370^2)+(0.5*SystemConstants!$B$7*SystemConstants!$B$2*SystemConstants!$B$3*Data!E370^2) -> 44.010925
A371: =A370+1 -> 369 | B371: =B370+(30/180) -> 21.5 | C371: =-2*B371+120 -> 77 | D371: 0 | E371: =ABS((SQRT(B371^2+C371^2+D371^2)-SQRT(B370^2+C370^2+D370^2))/(A371-A370)) -> 0.27662064 | F371: =(E371-E370)/(A371-A370) -> -0.00077479187 | G371: =DEGREES(ACOS( (B370*B371+C370*C371+D370*D371) / SQRT((B370^2+C370^2+D370^2)*(B371^2+C371^2+D371^2)))) -> 0.17867649 | H371: =(SystemConstants!$B$6*F371)+(0.5*SystemConstants!$B$7*SystemConstants!$B$5*Data!E371^2)+(0.5*SystemConstants!$B$7*SystemConstants!$B$2*SystemConstants!$B$3*Data!E371^2) -> 43.765403
A372: =A371+1 -> 370 | B372: =B371+(30/180) -> 21.666667 | C372: =-2*B372+120 -> 76.666667 | D372: 0 | E372: =ABS((SQRT(B372^2+C372^2+D372^2)-SQRT(B371^2+C371^2+D371^2))/(A372-A371)) -> 0.27583778 | F372: =(E372-E371)/(A372-A371) -> -0.00078286235 | G372: =DEGREES(ACOS( (B371*B372+C371*C372+D371*D372) / SQRT((B371^2+C371^2+D371^2)*(B372^2+C372^2+D372^2)))) -> 0.1799155 | H372: =(SystemConstants!$B$6*F372)+(0.5*SystemConstants!$B$7*SystemConstants!$B$5*Data!E372^2)+(0.5*SystemConstants!$B$7*SystemConstants!$B$2*SystemConstants!$B$3*Data!E372^2) -> 43.51802
A373: =A372+1 -> 371 | B373: =B372+(30/180) -> 21.833333 | C373: =-2*B373+120 -> 76.333333 | D373: 0 | E373: =ABS((SQRT(B373^2+C373^2+D373^2)-SQRT(B372^2+C372^2+D372^2))/(A373-A372)) -> 0.27504676 | F373: =(E373-E372)/(A373-A372) -> -0.00079102198 | G373: =DEGREES(ACOS( (B372*B373+C372*C373+D372*D373) / SQRT((B372^2+C372^2+D372^2)*(B373^2+C373^2+D373^2)))) -> 0.18116387 | H373: =(SystemConstants!$B$6*F373)+(0.5*SystemConstants!$B$7*SystemConstants!$B$5*Data!E373^2)+(0.5*SystemConstants!$B$7*SystemConstants!$B$2*SystemConstants!$B$3*Data!E373^2) -> 43.268772
A374: =A373+1 -> 372 | B374: =B373+(30/180) -> 22 | C374: =-2*B374+120 -> 76 | D374: 0 | E374: =ABS((SQRT(B374^2+C374^2+D374^2)-SQRT(B373^2+C373^2+D373^2))/(A374-A373)) -> 0.27424748 | F374: =(E374-E373)/(A374-A373) -> -0.00079927151 | G374: =DEGREES(ACOS( (B373*B374+C373*C374+D373*D374) / SQRT((B373^2+C373^2+D373^2)*(B374^2+C374^2+D374^2)))) -> 0.18242161 | H374: =(SystemConstants!$B$6*F374)+(0.5*SystemConstants!$B$7*SystemConstants!$B$5*Data!E374^2)+(0.5*SystemConstants!$B$7*SystemConstants!$B$2*SystemConstants!$B$3*Data!E374^2) -> 43.017651
...

Sheet SystemConstants
A1: Variable | B1: Value
A2: Kayak Drag Coefficient | B2: 0.5
A3: Kayak Wetted Area | B3: 2.123
A4: Paddle Drag Coefficient | B4: 1.2
A5: Paddle Wetted Area | B5: 0.06
A6: Mass of Paddle | B6: 1 | C6: kg
A7: Density of Water | B7: 1020
